<?xml version="1.0" encoding="utf-8"?>
<!-- This URDF was automatically created by SolidWorks to URDF Exporter! Originally created by Stephen Brawner (brawner@gmail.com) 
     Commit Version: 1.6.0-1-g15f4949  Build Version: 1.6.7594.29634
     For more information, please see http://wiki.ros.org/sw_urdf_exporter -->
<robot
  name="abb_irb360_support">
  <link
    name="base_link">
    <inertial>
      <origin
        xyz="-0.000146392333006221 0.000174197624304152 -0.194134116186906"
        rpy="0 0 0" />
      <mass
        value="49.2535162198679" />
      <inertia
        ixx="1.69410505731219"
        ixy="-0.00152124414047964"
        ixz="9.04824954495195E-05"
        iyy="1.69394309477089"
        iyz="-1.94947940218093E-06"
        izz="2.76809471792502" />
    </inertial>
    <visual>
      <origin
        xyz="0 0 0"
        rpy="0 0 0" />
      <geometry>
        <mesh
          filename="package://abb_irb360_support/meshes/base_link.STL" />
      </geometry>
      <material
        name="">
        <color
          rgba="1 1 1 1" />
      </material>
    </visual>
    <collision>
      <origin
        xyz="0 0 0"
        rpy="0 0 0" />
      <geometry>
        <mesh
          filename="package://abb_irb360_support/meshes/base_link.STL" />
      </geometry>
    </collision>
  </link>
  <joint
    name="uj_14"
    type="continuous">
    <origin
      xyz="0 0 0"
      rpy="-3.1416 0.50922 -3.1416" />
    <parent
      link="ul_2" />
    <child
      link="end_plate" />
    <axis
      xyz="0 1 0" />
  </joint>
  <link
    name="upper_arm_1">
    <inertial>
      <origin
        xyz="0.090456 0.0020029 -0.00021572"
        rpy="0 0 0" />
      <mass
        value="0.91849" />
      <inertia
        ixx="0.0005804"
        ixy="0.00015655"
        ixz="2.754E-05"
        iyy="0.0065175"
        iyz="-3.9597E-07"
        izz="0.0065861" />
    </inertial>
    <visual>
      <origin
        xyz="0 0 0"
        rpy="0 0 0" />
      <geometry>
        <mesh
          filename="package://abb_irb360_support/meshes/upper_arm_1.STL" />
      </geometry>
      <material
        name="">
        <color
          rgba="1 1 1 1" />
      </material>
    </visual>
    <collision>
      <origin
        xyz="0 0 0"
        rpy="0 0 0" />
      <geometry>
        <mesh
          filename="package://abb_irb360_support/meshes/upper_arm_1.STL" />
      </geometry>
    </collision>
  </link>
  <joint
    name="joint_1"
    type="continuous">
    <origin
      xyz="0.2 0 -0.275"
      rpy="0 -0.115268716889166 0" />
    <parent
      link="base_link" />
    <child
      link="upper_arm_1" />
    <axis
      xyz="0 1 0" />
    <limit
      lower="0"
      upper="0"
      effort="0"
      velocity="0" />
  </joint>
  <link
    name="upper_universal_link_1">
    <inertial>
      <origin
        xyz="6.4055E-10 1.1269E-09 4.9485E-11"
        rpy="0 0 0" />
      <mass
        value="0.0087708" />
      <inertia
        ixx="1.1933E-06"
        ixy="1.7189E-16"
        ixz="1.0906E-15"
        iyy="1.798E-07"
        iyz="-3.0639E-14"
        izz="1.1877E-06" />
    </inertial>
    <visual>
      <origin
        xyz="0 0 0"
        rpy="0 0 0" />
      <geometry>
        <mesh
          filename="package://abb_irb360_support/meshes/upper_universal_link_1.STL" />
      </geometry>
      <material
        name="">
        <color
          rgba="1 1 1 1" />
      </material>
    </visual>
    <collision>
      <origin
        xyz="0 0 0"
        rpy="0 0 0" />
      <geometry>
        <mesh
          filename="package://abb_irb360_support/meshes/upper_universal_link_1.STL" />
      </geometry>
    </collision>
  </link>
  <joint
    name="uj_11"
    type="continuous">
    <origin
      xyz="0.233443783382638 0 -0.0269999999999995"
      rpy="0 0.624492885969242 0" />
    <parent
      link="upper_arm_1" />
    <child
      link="upper_universal_link_1" />
    <axis
      xyz="0 1 0" />
  </joint>
  <link
    name="lower_arm_1">
    <inertial>
      <origin
        xyz="0.40002 9.7445E-08 -0.00028547"
        rpy="0 0 0" />
      <mass
        value="0.13022" />
      <inertia
        ixx="3.6844E-06"
        ixy="7.9891E-09"
        ixz="1.2589E-08"
        iyy="0.0075678"
        iyz="4.8228E-10"
        izz="0.0075679" />
    </inertial>
    <visual>
      <origin
        xyz="0 0 0"
        rpy="0 0 0" />
      <geometry>
        <mesh
          filename="package://abb_irb360_support/meshes/lower_arm_1.STL" />
      </geometry>
      <material
        name="">
        <color
          rgba="1 1 1 1" />
      </material>
    </visual>
    <collision>
      <origin
        xyz="0 0 0"
        rpy="0 0 0" />
      <geometry>
        <mesh
          filename="package://abb_irb360_support/meshes/lower_arm_1.STL" />
      </geometry>
    </collision>
  </link>
  <joint
    name="uj_12"
    type="continuous">
    <origin
      xyz="0 0 0"
      rpy="1.5707963267949 1.5707963267949 0" />
    <parent
      link="upper_universal_link_1" />
    <child
      link="lower_arm_1" />
    <axis
      xyz="0 1 0" />
  </joint>
  <link
    name="lower_universal_link_1">
    <inertial>
      <origin
        xyz="4.87E-10 1.2133E-10 3.376E-11"
        rpy="0 0 0" />
      <mass
        value="0.0087708" />
      <inertia
        ixx="1.1933E-06"
        ixy="6.4199E-17"
        ixz="1.2294E-15"
        iyy="1.798E-07"
        iyz="-2.9093E-14"
        izz="1.1877E-06" />
    </inertial>
    <visual>
      <origin
        xyz="0 0 0"
        rpy="0 0 0" />
      <geometry>
        <mesh
          filename="package://abb_irb360_support/meshes/lower_universal_link_1.STL" />
      </geometry>
      <material
        name="">
        <color
          rgba="1 1 1 1" />
      </material>
    </visual>
    <collision>
      <origin
        xyz="0 0 0"
        rpy="0 0 0" />
      <geometry>
        <mesh
          filename="package://abb_irb360_support/meshes/lower_universal_link_1.STL" />
      </geometry>
    </collision>
  </link>
  <joint
    name="uj_13"
    type="continuous">
    <origin
      xyz="0.799999999999999 0 0"
      rpy="-1.5707963267949 0 -1.5707963267949" />
    <parent
      link="lower_arm_1" />
    <child
      link="lower_universal_link_1" />
    <axis
      xyz="1 0 0" />
  </joint>
  <link
    name="moving_platform">
    <inertial>
      <origin
        xyz="-0.045017 3.0342E-05 -0.0066174"
        rpy="0 0 0" />
      <mass
        value="0.12295" />
      <inertia
        ixx="7.8175E-05"
        ixy="-5.9221E-08"
        ixz="-3.398E-08"
        iyy="7.8242E-05"
        iyz="5.9096E-08"
        izz="0.00012544" />
    </inertial>
    <visual>
      <origin
        xyz="0 0 0"
        rpy="0 0 0" />
      <geometry>
        <mesh
          filename="package://abb_irb360_support/meshes/moving_platform.STL" />
      </geometry>
      <material
        name="">
        <color
          rgba="1 1 1 1" />
      </material>
    </visual>
    <collision>
      <origin
        xyz="0 0 0"
        rpy="0 0 0" />
      <geometry>
        <mesh
          filename="package://abb_irb360_support/meshes/moving_platform.STL" />
      </geometry>
    </collision>
  </link>
  <joint
    name="uj_14"
    type="continuous">
    <origin
      xyz="0 0 0"
      rpy="-3.14159265358979 0.509224169080082 -3.14159265358979" />
    <parent
      link="lower_universal_link_1" />
    <child
      link="moving_platform" />
    <axis
      xyz="0 1 0" />
  </joint>
  <link
    name="end_link">
    <inertial>
      <origin
        xyz="8.442E-06 2.1629E-05 -0.0057733"
        rpy="0 0 0" />
      <mass
        value="0.020194" />
      <inertia
        ixx="8.0776E-06"
        ixy="-8.1216E-08"
        ixz="2.2389E-08"
        iyy="8.1203E-06"
        iyz="-7.1107E-09"
        izz="1.8224E-06" />
    </inertial>
    <visual>
      <origin
        xyz="0 0 0"
        rpy="0 0 0" />
      <geometry>
        <mesh
          filename="package://abb_irb360_support/meshes/end_link.STL" />
      </geometry>
      <material
        name="">
        <color
          rgba="1 1 1 1" />
      </material>
    </visual>
    <collision>
      <origin
        xyz="0 0 0"
        rpy="0 0 0" />
      <geometry>
        <mesh
          filename="package://abb_irb360_support/meshes/end_link.STL" />
      </geometry>
    </collision>
  </link>
  <joint
    name="joint_4"
    type="continuous">
    <origin
      xyz="-0.0449999999999976 0 0"
      rpy="0 0 0" />
    <parent
      link="moving_platform" />
    <child
      link="end_link" />
    <axis
      xyz="0 0 1" />
  </joint>
  <link
    name="upper_arm_2">
    <inertial>
      <origin
        xyz="0 0 0"
        rpy="0 0 0" />
      <mass
        value="0" />
      <inertia
        ixx="0"
        ixy="0"
        ixz="0"
        iyy="0"
        iyz="0"
        izz="0" />
    </inertial>
    <visual>
      <origin
        xyz="0 0 0"
        rpy="0 0 0" />
      <geometry>
        <mesh
          filename="package://abb_irb360_support/meshes/upper_arm_2.STL" />
      </geometry>
      <material
        name="">
        <color
          rgba="1 1 1 1" />
      </material>
    </visual>
    <collision>
      <origin
        xyz="0 0 0"
        rpy="0 0 0" />
      <geometry>
        <mesh
          filename="package://abb_irb360_support/meshes/upper_arm_2.STL" />
      </geometry>
    </collision>
  </link>
  <joint
    name="joint_2"
    type="fixed">
    <origin
      xyz="-0.1 -0.17321 -0.275"
      rpy="0 -0.11527 -2.0944" />
    <parent
      link="base_link" />
    <child
      link="upper_arm_2" />
    <axis
      xyz="0 0 0" />
  </joint>
  <link
    name="upper_universal_link_2">
    <inertial>
      <origin
        xyz="0 0 0"
        rpy="0 0 0" />
      <mass
        value="0" />
      <inertia
        ixx="0"
        ixy="0"
        ixz="0"
        iyy="0"
        iyz="0"
        izz="0" />
    </inertial>
    <visual>
      <origin
        xyz="0 0 0"
        rpy="0 0 0" />
      <geometry>
        <mesh
          filename="package://abb_irb360_support/meshes/upper_universal_link_2.STL" />
      </geometry>
      <material
        name="">
        <color
          rgba="1 1 1 1" />
      </material>
    </visual>
    <collision>
      <origin
        xyz="0 0 0"
        rpy="0 0 0" />
      <geometry>
        <mesh
          filename="package://abb_irb360_support/meshes/upper_universal_link_2.STL" />
      </geometry>
    </collision>
  </link>
  <joint
    name="uj_21"
    type="fixed">
    <origin
      xyz="0.23344 0 -0.027"
      rpy="-1.5708 0.9463 3.1416" />
    <parent
      link="upper_arm_2" />
    <child
      link="upper_universal_link_2" />
    <axis
      xyz="0 0 0" />
  </joint>
  <link
    name="upper_arm_3">
    <inertial>
      <origin
        xyz="0 0 0"
        rpy="0 0 0" />
      <mass
        value="0" />
      <inertia
        ixx="0"
        ixy="0"
        ixz="0"
        iyy="0"
        iyz="0"
        izz="0" />
    </inertial>
    <visual>
      <origin
        xyz="0 0 0"
        rpy="0 0 0" />
      <geometry>
        <mesh
          filename="package://abb_irb360_support/meshes/upper_arm_3.STL" />
      </geometry>
      <material
        name="">
        <color
          rgba="1 1 1 1" />
      </material>
    </visual>
    <collision>
      <origin
        xyz="0 0 0"
        rpy="0 0 0" />
      <geometry>
        <mesh
          filename="package://abb_irb360_support/meshes/upper_arm_3.STL" />
      </geometry>
    </collision>
  </link>
  <joint
    name="joint_3"
    type="fixed">
    <origin
      xyz="-0.1 0.17321 -0.275"
      rpy="0 -0.11527 2.0944" />
    <parent
      link="base_link" />
    <child
      link="upper_arm_3" />
    <axis
      xyz="0 0 0" />
  </joint>
  <link
    name="upper_universal_link_3">
    <inertial>
      <origin
        xyz="0 0 0"
        rpy="0 0 0" />
      <mass
        value="0" />
      <inertia
        ixx="0"
        ixy="0"
        ixz="0"
        iyy="0"
        iyz="0"
        izz="0" />
    </inertial>
    <visual>
      <origin
        xyz="0 0 0"
        rpy="0 0 0" />
      <geometry>
        <mesh
          filename="package://abb_irb360_support/meshes/upper_universal_link_3.STL" />
      </geometry>
      <material
        name="">
        <color
          rgba="1 1 1 1" />
      </material>
    </visual>
    <collision>
      <origin
        xyz="0 0 0"
        rpy="0 0 0" />
      <geometry>
        <mesh
          filename="package://abb_irb360_support/meshes/upper_universal_link_3.STL" />
      </geometry>
    </collision>
  </link>
  <joint
    name="uj_31"
    type="fixed">
    <origin
      xyz="0.23344 0 -0.027"
      rpy="-1.5708 0.9463 -3.1416" />
    <parent
      link="upper_arm_3" />
    <child
      link="upper_universal_link_3" />
    <axis
      xyz="0 0 0" />
  </joint>
</robot>