<?xml version="1.0" encoding="utf-8"?>
<!-- This URDF was automatically created by SolidWorks to URDF Exporter! Originally created by Stephen Brawner (brawner@gmail.com) 
     Commit Version: 1.6.0-1-g15f4949  Build Version: 1.6.7594.29634
     For more information, please see http://wiki.ros.org/sw_urdf_exporter -->
<robot name="abb_irb360_support">

  <!-- Links list -->
  <link name="base_link">
    <visual>
      <origin xyz="0 0 0" rpy="0 0 0" />
      <geometry>
        <mesh filename="package://abb_irb360_support/meshes/base_link.STL" />
      </geometry>
      <material name="">
        <color rgba="0.745098039215686 0.745098039215686 0.745098039215686 1" />
      </material>
    </visual>
    <collision>
      <origin xyz="0 0 0" rpy="0 0 0" />
      <geometry>
        <mesh filename="package://abb_irb360_support/meshes/base_link.STL" />
      </geometry>
    </collision>
  </link>
  <link name="upper_arm_1">
    <visual>
      <origin xyz="0 0 0" rpy="0 0 0" />
      <geometry>
        <mesh filename="package://abb_irb360_support/meshes/upper_arm_1.STL" />
      </geometry>
      <material name="">
        <color rgba="0.7451 0.7451 0.7451 1" />
      </material>
    </visual>
    <collision>
      <origin xyz="0 0 0" rpy="0 0 0" />
      <geometry>
        <mesh filename="package://abb_irb360_support/meshes/upper_arm_1.STL" />
      </geometry>
    </collision>
  </link>
  <link name="upper_universal_link_1">
    <visual>
      <origin xyz="0 0 0" rpy="0 0 0" />
      <geometry>
        <mesh filename="package://abb_irb360_support/meshes/upper_universal_link_1.STL" />
      </geometry>
      <material name="">
        <color rgba="0.49804 0.49804 0.46275 1" />
      </material>
    </visual>
    <collision>
      <origin xyz="0 0 0" rpy="0 0 0" />
      <geometry>
        <mesh filename="package://abb_irb360_support/meshes/upper_universal_link_1.STL" />
      </geometry>
    </collision>
  </link>
  <link name="lower_arm_1">
    <visual>
      <origin xyz="0 0 0" rpy="0 0 0" />
      <geometry>
        <mesh filename="package://abb_irb360_support/meshes/lower_arm_1.STL" />
      </geometry>
      <material name="">
        <color rgba="0.7451 0.7451 0.7451 1" />
      </material>
    </visual>
    <collision>
      <origin xyz="0 0 0" rpy="0 0 0" />
      <geometry>
        <mesh filename="package://abb_irb360_support/meshes/lower_arm_1.STL" />
      </geometry>
    </collision>
  </link>
  <link name="lower_universal_link_1">
    <visual>
      <origin xyz="0 0 0" rpy="0 0 0" />
      <geometry>
        <mesh filename="package://abb_irb360_support/meshes/lower_universal_link_1.STL" />
      </geometry>
      <material name="">
        <color rgba="0.49804 0.49804 0.46275 1" />
      </material>
    </visual>
    <collision>
      <origin xyz="0 0 0" rpy="0 0 0" />
      <geometry>
        <mesh filename="package://abb_irb360_support/meshes/lower_universal_link_1.STL" />
      </geometry>
    </collision>
  </link>
  <link name="moving_platform">
    <visual>
      <origin xyz="0 0 0" rpy="0 0 0" />
      <geometry>
        <mesh filename="package://abb_irb360_support/meshes/moving_platform.STL" />
      </geometry>
      <material name="">
        <color rgba="0.7451 0.7451 0.7451 1" />
      </material>
    </visual>
    <collision>
      <origin xyz="0 0 0" rpy="0 0 0" />
      <geometry>
        <mesh filename="package://abb_irb360_support/meshes/moving_platform.STL" />
      </geometry>
    </collision>
  </link>
  <link name="end_link">
    <visual>
      <origin xyz="0 0 0" rpy="0 0 0" />
      <geometry>
        <mesh filename="package://abb_irb360_support/meshes/end_link.STL" />
      </geometry>
      <material name="">
        <color rgba="0.7451 0.7451 0.7451 1" />
      </material>
    </visual>
    <collision>
      <origin xyz="0 0 0" rpy="0 0 0" />
      <geometry>
        <mesh filename="package://abb_irb360_support/meshes/end_link.STL" />
      </geometry>
    </collision>
  </link>

  <!-- Joints list -->
  <joint name="joint_1" type="continuous">
    <origin xyz="0.2 0 -0.275" rpy="0 -0.11527 0" />
    <parent link="base_link" />
    <child link="upper_arm_1" />
    <axis xyz="0 1 0" />
    <limit lower="0" upper="0" effort="0" velocity="0" />
  </joint>
  <joint name="joint_4" type="continuous">
    <origin xyz="-0.045 0 0" rpy="0 0 0" />
    <parent link="moving_platform" />
    <child link="end_link" />
    <axis xyz="0 0 1" />
  </joint>
  <joint name="uj_11" type="continuous">
    <origin xyz="0.23344 0 -0.027" rpy="0 0.62449 0" />
    <parent link="upper_arm_1" />
    <child link="upper_universal_link_1" />
    <axis xyz="0 1 0" />
  </joint>
  <joint name="uj_12" type="continuous">
    <origin xyz="0 0 0" rpy="1.5708 1.5708 0" />
    <parent link="upper_universal_link_1" />
    <child link="lower_arm_1" />
    <axis xyz="0 1 0" />
  </joint>
  <joint name="uj_13" type="continuous">
    <origin xyz="0.8 0 0" rpy="-1.5708 0 -1.5708" />
    <parent link="lower_arm_1" />
    <child link="lower_universal_link_1" />
    <axis xyz="1 0 0" />
  </joint>
  <joint name="uj_14" type="continuous">
    <origin xyz="0 0 0" rpy="-3.1416 0.50922 -3.1416" />
    <parent link="lower_universal_link_1" />
    <child link="moving_platform" />
    <axis xyz="0 1 0" />
  </joint>

</robot>